Workbook

Sheet Resumen
A1: ACTIVIDAD APLICATIVA N° 07
A2: Empresa Mi Alto Perú - Planilla de Remuneraciones - Régimen Construcción Civil
A3: Período: 06/04 al 11/04 (6 días) | Curso: Contabilidad Sectorial | Dra. Luz R. Lapa Salinas | Ciclo VI – Noche
A5: CUADRO COMPARATIVO
A7: Concepto | B7: Cruz Alonso (Operario) | C7: Salas Diego (Oficial) | D7: Pérez Gino (Peón) | E7: Totales
A8: Jornal semanal | B8: ='T1 - Cruz Alonso'!D11 -> 535.8 | C8: ='T2 - Salas Diego'!D11 -> 418.5 | D8: ='T3 - Pérez Gino'!D11 -> 376.8 | E8: =SUM(B8:D8) -> 1331.1
A9: DSO | B9: ='T1 - Cruz Alonso'!D15 -> 89.3 | C9: ='T2 - Salas Diego'!D15 -> 69.75 | D9: ='T3 - Pérez Gino'!D15 -> 62.8 | E9: =SUM(B9:D9) -> 221.85
A10: BUC | B10: ='T1 - Cruz Alonso'!D19 -> 171.456 | C10: ='T2 - Salas Diego'!D19 -> 125.55 | D10: ='T3 - Pérez Gino'!D19 -> 113.04 | E10: =SUM(B10:D10) -> 410.046
A11: Movilidad | B11: ='T1 - Cruz Alonso'!D23 -> 51.6 | C11: ='T2 - Salas Diego'!D23 -> 51.6 | D11: ='T3 - Pérez Gino'!D23 -> 51.6 | E11: =SUM(B11:D11) -> 154.8
A12: Bonif. altitud | B12: 0 | C12: ='T2 - Salas Diego'!D27 -> 15 | D12: ='T3 - Pérez Gino'!D27 -> 15 | E12: =SUM(B12:D12) -> 30
A13: Bonif. altura | B13: 0 | C13: ='T2 - Salas Diego'!F31 -> 33.48 | D13: 0 | E13: =SUM(B13:D13) -> 33.48
A14: Indemnización CTS | B14: ='T1 - Cruz Alonso'!D27 -> 80.37 | C14: ='T2 - Salas Diego'!D35 -> 62.775 | D14: ='T3 - Pérez Gino'!D31 -> 56.52 | E14: =SUM(B14:D14) -> 199.665
A15: Vacaciones | B15: ='T1 - Cruz Alonso'!D31 -> 53.58 | C15: ='T2 - Salas Diego'!D39 -> 41.85 | D15: ='T3 - Pérez Gino'!D35 -> 37.68 | E15: =SUM(B15:D15) -> 133.11
A16: Gratificaciones | B16: ='T1 - Cruz Alonso'!E36 -> 119.06667 | C16: ='T2 - Salas Diego'!E44 -> 93 | D16: ='T3 - Pérez Gino'!E40 -> 83.733333 | E16: =SUM(B16:D16) -> 295.8
A17: Bonificación extraord. | B17: ='T1 - Cruz Alonso'!D40 -> 10.716 | C17: ='T2 - Salas Diego'!D48 -> 8.37 | D17: ='T3 - Pérez Gino'!D44 -> 7.536 | E17: =SUM(B17:D17) -> 26.622
A18: Asignación escolar | B18: ='T1 - Cruz Alonso'!F45 -> 104.18333 | C18: ='T2 - Salas Diego'!F53 -> 40.6875 | D18: ='T3 - Pérez Gino'!F48 -> 0 | E18: =SUM(B18:D18) -> 144.87083
A19: Horas extra | B19: ='T1 - Cruz Alonso'!E54 -> 174.135 | C19: ='T2 - Salas Diego'!E62 -> 160.425 | D19: ='T3 - Pérez Gino'!E57 -> 25.12 | E19: =SUM(B19:D19) -> 359.68
A20: Indemnización HE | B20: ='T1 - Cruz Alonso'!D58 -> 100.44 | C20: ='T2 - Salas Diego'!D66 -> 87.2 | D20: ='T3 - Pérez Gino'!D61 -> 15.7 | E20: =SUM(B20:D20) -> 203.34
A22: TOTAL INGRESOS BRUTOS | B22: ='T1 - Cruz Alonso'!D61 -> 1490.647 | C22: ='T2 - Salas Diego'!D69 -> 1180.2875 | D22: ='T3 - Pérez Gino'!D64 -> 845.52933 | E22: =SUM(B22:D22) -> 3516.4638
A23: Base afecta | B23: ='T1 - Cruz Alonso'!D65 -> 1128.4543 | C23: ='T2 - Salas Diego'!D73 -> 905.2425 | D23: ='T3 - Pérez Gino'!D68 -> 630.44 | E23: =SUM(B23:D23) -> 2664.1368
A24: Total descuentos (ONP+CONAFOVICER) | B24: ='T1 - Cruz Alonso'!C72 -> 169.26815 | C24: ='T2 - Salas Diego'!C80 -> 135.78638 | D24: ='T3 - Pérez Gino'!C75 -> 94.566 | E24: =SUM(B24:D24) -> 399.62053
A25: SALARIO NETO A PAGAR | B25: ='T1 - Cruz Alonso'!D74 -> 1321.3789 | C25: ='T2 - Salas Diego'!D82 -> 1044.5011 | D25: ='T3 - Pérez Gino'!D77 -> 750.96333 | E25: =SUM(B25:D25) -> 3116.8433
A26: Total aportes empleador (ESSALUD+SENCICO) | B26: ='T1 - Cruz Alonso'!C80 -> 103.8178 | C26: ='T2 - Salas Diego'!C88 -> 83.28231 | D26: ='T3 - Pérez Gino'!C83 -> 58.00048 | E26: =SUM(B26:D26) -> 245.10059
A27: COSTO TOTAL EMPRESA | B27: ='T1 - Cruz Alonso'!D83 -> 1594.4648 | C27: ='T2 - Salas Diego'!D91 -> 1263.5698 | D27: ='T3 - Pérez Gino'!D86 -> 903.52981 | E27: =SUM(B27:D27) -> 3761.5644
A30: Nota metodológica:
A31: • Régimen: Construcción Civil (D. Leg. 727 y convenios colectivos vigentes).
A32: • Jornales básicos: Operario S/ 89.30 | Oficial S/ 69.75 | Peón S/ 62.80.
A33: • BUC: 32% operario / 30% oficial / 30% peón sobre jornal básico × días trabajados.
A34: • CTS = 15% del jornal semanal | Vacaciones = 10% del jornal semanal.
A35: • Gratificaciones = 40 jornales prorrateados (jornal × 40 / 7 / 30 × 7 días).
A36: • Bonificación extraordinaria = 9% de la gratificación (Ley 30334).
A37: • Asignación escolar = jornal × 30 / 360 × 7 × N° hijos en edad escolar.
A38: • HE: 1ras 2 diarias al 60% de recargo, desde la 3ra al 100%.
A39: • Bonif. altitud: S/ 2.50/día (> 3,000 msnm). Bonif. altura: 8% del jornal por cada 4 pisos (desde el 4° piso).
A40: • Base afecta: jornal semanal + DSO + BUC + vacaciones + asignación familiar + HE + altitud + altura.
A41: • Descuentos: ONP 13% | CONAFOVICER 2%. Aportes empleador: ESSALUD 9% | SENCICO 0.2%.

Sheet T1 - Cruz Alonso
A1: EMPRESA MI ALTO PERÚ - CONSTRUCTORA
A2: Planilla de Remuneraciones - Régimen Construcción Civil
A4: Trabajador: | B4: Cruz Alonso
A5: Categoría: | B5: Operario
A6: Período: | B6: 06/04 al 11/04 (6 días)
A7: Régimen pensionario: | B7: ONP
A9: 1. JORNADA SEMANAL
A10: Jornal básico × días trabajados
A11: Jornal básico (S/) | B11: 89.3 | C11: 6 días | D11: =B11*6 -> 535.8
A13: 2. DESCANSO SEMANAL OBLIGATORIO
A14: Equivale a 1 jornal diario
B15: =B11 -> 89.3 | C15: 1 día | D15: =B15 -> 89.3
A17: 3. BONIFICACIÓN UNIFICADA DE CONSTRUCCIÓN (BUC)
A18: Operario: 32% del jornal diario por día trabajado
B19: =D11 -> 535.8 | C19: 0.32 | D19: =B19*C19 -> 171.456
A21: 4. MOVILIDAD
A22: S/ 8.60 por día trabajado
B23: 8.6 | C23: 6 días | D23: =B23*6 -> 51.6
A25: 7. INDEMNIZACIÓN CTS
A26: 15% del jornal semanal | F26: ESTO NO ESTA EN LA TEORIA, PERO APARECE EN TODOS
B27: =D11 -> 535.8 | C27: 0.15 | D27: =B27*C27 -> 80.37
A29: 8. VACACIONES
A30: 10% del jornal semanal
B31: =D11 -> 535.8 | C31: 0.1 | D31: =B31*C31 -> 53.58
A33: 9. GRATIFICACIONES
A34: 40 jornales anuales prorrateados (jornal × 40 / 7 / 30)
A35: Cálculo base (por día): | B35: =B11 -> 89.3 | C35: 40 | D35: =B35*C35 -> 3572 | E35: 7 | F35: 30 | G35: =D35/E35/F35 -> 17.009524
A36: Aplicado a la semana (× 7 días): | C36: =G35 -> 17.009524 | D36: 7 | E36: =C36*D36 -> 119.06667
A38: 10. BONIFICACIÓN EXTRAORDINARIA
A39: 9% de la gratificación (Ley 30334) | F39: ESTO NO ESTA EN LA TEORIA, PERO APARECE EN TODOS
B40: =E36 -> 119.06667 | C40: 0.09 | D40: =B40*C40 -> 10.716
A42: 11. ASIGNACIÓN ESCOLAR (Escolaridad)
A43: 30 jornales × jornal diario / 360 días × 7 días × N° hijos en edad escolar
B44: =B11 -> 89.3 | C44: 30 | D44: 360 | E44: 7 | F44: =B44*C44/D44*E44 -> 52.091667
D45: Por hijo | E45: 2 | F45: =F44*E45 -> 104.18333
A47: 12. HORAS EXTRA
A48: En función al jornal diario (3d × 3h)
A49: Valor hora ordinaria: | C49: =B11 -> 89.3 | D49: 8 | E49: =C49/D49 -> 11.1625
C51: HE | D51: Valor hora | E51: Total
A52: 60% (1ras 2 HE diarias) | B52: 0.6 | C52: 6 | D52: =E49 -> 11.1625 | E52: =D52*(B52+1)*C52 -> 107.16
...

Sheet T2 - Salas Diego
A1: EMPRESA MI ALTO PERÚ - CONSTRUCTORA
A2: Planilla de Remuneraciones - Régimen Construcción Civil
A4: Trabajador: | B4: Salas Diego
A5: Categoría: | B5: Oficial
A6: Período: | B6: 06/04 al 11/04 (6 días)
A7: Régimen pensionario: | B7: ONP
A9: 1. JORNADA SEMANAL
A10: Jornal básico × días trabajados
A11: Jornal básico (S/) | B11: 69.75 | C11: 6 días | D11: =B11*6 -> 418.5
A13: 2. DESCANSO SEMANAL OBLIGATORIO
A14: Equivale a 1 jornal diario
B15: =B11 -> 69.75 | C15: 1 día | D15: =B15 -> 69.75
A17: 3. BONIFICACIÓN UNIFICADA DE CONSTRUCCIÓN (BUC)
A18: Oficial: 30% del jornal diario por día trabajado
B19: =D11 -> 418.5 | C19: 0.3 | D19: =B19*C19 -> 125.55
A21: 4. MOVILIDAD
A22: S/ 8.60 por día trabajado
B23: 8.6 | C23: 6 días | D23: =B23*6 -> 51.6
A25: 5. BONIFICACIÓN POR ALTITUD
A26: S/ 2.50 por día trabajado (obra > 3,000 msnm)
B27: 2.5 | C27: 6 días | D27: =B27*6 -> 15 | E27: si se multiplica por dias
A29: 6. BONIFICACIÓN POR ALTURA
A30: 8% sobre jornal básico por cada 4 pisos (a partir del 4°). Obra de 7 pisos → 8% | F30: La profe dice que no se multiplica por dias laborados | J30: PREGUNTAR SI, CUANDO HAY MAS DE 8 PISOS, ME DEBERAN PAGAR 16% O SOLO SE MANTIENE EL 8%
B31: =B11 -> 69.75 | C31: 0.08 | D31: =B31*C31 -> 5.58 | E31: 6 días | F31: =D31*6 -> 33.48
A33: 7. INDEMNIZACIÓN CTS
A34: 15% del jornal semanal
B35: =D11 -> 418.5 | C35: 0.15 | D35: =B35*C35 -> 62.775
A37: 8. VACACIONES
A38: 10% del jornal semanal
B39: =D11 -> 418.5 | C39: 0.1 | D39: =B39*C39 -> 41.85
A41: 9. GRATIFICACIONES
A42: 40 jornales anuales prorrateados (jornal × 40 / 7 / 30)
A43: Cálculo base (por día): | B43: =B11 -> 69.75 | C43: 40 | D43: =B43*C43 -> 2790 | E43: 7 | F43: 30 | G43: =D43/E43/F43 -> 13.285714
A44: Aplicado a la semana (× 7 días): | C44: =G43 -> 13.285714 | D44: 7 | E44: =C44*D44 -> 93
A46: 10. BONIFICACIÓN EXTRAORDINARIA
A47: 9% de la gratificación (Ley 30334)
B48: =E44 -> 93 | C48: 0.09 | D48: =B48*C48 -> 8.37
A50: 11. ASIGNACIÓN ESCOLAR
A51: 30 jornales × jornal diario / 360 días × 7 días × N° hijos en edad escolar
B52: =B11 -> 69.75 | C52: 30 | D52: 360 | E52: 7 | F52: =B52*C52/D52*E52 -> 40.6875
...

Sheet T3 - Pérez Gino
A1: EMPRESA MI ALTO PERÚ - CONSTRUCTORA
A2: Planilla de Remuneraciones - Régimen Construcción Civil
A4: Trabajador: | B4: Pérez Gino
A5: Categoría: | B5: Peón
A6: Período: | B6: 06/04 al 11/04 (6 días)
A7: Régimen pensionario: | B7: ONP
A9: 1. JORNADA SEMANAL
A10: Jornal básico × días trabajados
A11: Jornal básico (S/) | B11: 62.8 | C11: 6 días | D11: =B11*6 -> 376.8
A13: 2. DESCANSO SEMANAL OBLIGATORIO
A14: Equivale a 1 jornal diario
B15: =B11 -> 62.8 | C15: 1 día | D15: =B15 -> 62.8
A17: 3. BONIFICACIÓN UNIFICADA DE CONSTRUCCIÓN (BUC)
A18: Peón: 30% del jornal diario por día trabajado
B19: =D11 -> 376.8 | C19: 0.3 | D19: =B19*C19 -> 113.04
A21: 4. MOVILIDAD
A22: S/ 8.60 por día trabajado
B23: 8.6 | C23: 6 días | D23: =B23*6 -> 51.6
A25: 5. BONIFICACIÓN POR ALTITUD
A26: S/ 2.50 por día trabajado (obra > 3,000 msnm)
B27: 2.5 | C27: 6 días | D27: =B27*6 -> 15
A29: 7. INDEMNIZACIÓN CTS
A30: 15% del jornal semanal
B31: =D11 -> 376.8 | C31: 0.15 | D31: =B31*C31 -> 56.52
A33: 8. VACACIONES
A34: 10% del jornal semanal
B35: =D11 -> 376.8 | C35: 0.1 | D35: =B35*C35 -> 37.68
A37: 9. GRATIFICACIONES
A38: 40 jornales anuales prorrateados (jornal × 40 / 7 / 30)
A39: Cálculo base (por día): | B39: =B11 -> 62.8 | C39: 40 | D39: =B39*C39 -> 2512 | E39: 7 | F39: 30 | G39: =D39/E39/F39 -> 11.961905
A40: Aplicado a la semana (× 7 días): | C40: =G39 -> 11.961905 | D40: 7 | E40: =C40*D40 -> 83.733333
A42: 10. BONIFICACIÓN EXTRAORDINARIA
A43: 9% de la gratificación (Ley 30334)
B44: =E40 -> 83.733333 | C44: 0.09 | D44: =B44*C44 -> 7.536
A46: 11. ASIGNACIÓN ESCOLAR
A47: No aplica (sin hijos en edad escolar)
F48: 0
A50: 12. HORAS EXTRA
A51: En función al jornal diario (2d × 1h)
A52: Valor hora ordinaria: | C52: =B11 -> 62.8 | D52: 8 | E52: =C52/D52 -> 7.85
...
